Workbook

Sheet CRFDraft
A1: DraftName | B1: DeleteExisting | C1: ProjectName | D1: ProjectType | E1: PrimaryFormOID | F1: DefaultMatrixOID | G1: ConfirmationMessage | H1: SignaturePrompt | I1: LabStandardGroup | J1: ReferenceLabs | K1: AlertLabs | L1: SyncOIDProject | M1: SyncOIDDraft | N1: SyncOIDProjectType | O1: SyncOIDOriginIsVersion | P1: SourceUrlId
A2: D8318N00001_V1.0_17Oct2025 | B2: FALSE | C2: D8318N00001 | D2: Project | E2: SC | F2: DEFAULT | G2: Form Saved. | H2: I certify that I have reviewed all data marked by this electronic signature and verify that the information is complete, accurate and consistent with the subject's source data records. | N2: Project | O2: FALSE | P2: az-cn | GR2: =IF(LEN(Forms!$A2)>0,Forms!$A2,"") -> SC
GR3: =IF(LEN(Forms!$A3)>0,Forms!$A3,"") -> SV
GR4: =IF(LEN(Forms!$A4)>0,Forms!$A4,"") -> UNSCH
GR5: =IF(LEN(Forms!$A5)>0,Forms!$A5,"") -> DS1_IC
GR6: =IF(LEN(Forms!$A6)>0,Forms!$A6,"") -> DM
GR7: =IF(LEN(Forms!$A7)>0,Forms!$A7,"") -> MH
GR8: =IF(LEN(Forms!$A8)>0,Forms!$A8,"") -> CM1
GR9: =IF(LEN(Forms!$A9)>0,Forms!$A9,"") -> PR2
GR10: =IF(LEN(Forms!$A10)>0,Forms!$A10,"") -> SU
GR11: =IF(LEN(Forms!$A11)>0,Forms!$A11,"") -> PR1
GR12: =IF(LEN(Forms!$A12)>0,Forms!$A12,"") -> HEI
GR13: =IF(LEN(Forms!$A13)>0,Forms!$A13,"") -> WEI
GR14: =IF(LEN(Forms!$A14)>0,Forms!$A14,"") -> CV1
... GR124: =IF(LEN(Forms!$A124)>0,Forms!$A124,"")

Sheet Forms
A1: OID | B1: Ordinal | C1: DraftFormName | D1: DraftFormActive | E1: HelpText | F1: IsTemplate | G1: IsSignatureRequired | H1: IsEproForm | I1: ViewRestrictions | J1: EntryRestrictions | K1: LogDirection | L1: DDEOption | M1: ConfirmationStyle | N1: LinkFolderOID | O1: LinkFormOID | P1: DownloadedFromObjectId | Q1: SourceObjectId | R1: SourceUrlId
A2: SC | B2: 1 | C2: Participant Information | D2: TRUE | E2: https://az-cn.mdsol.com/MedidataRave/Help/Modules/Helpfile/D8318N00001_eCRF_Completion_Guidelines.pdf | F2: FALSE | G2: TRUE | H2: FALSE | J2: Site Monitor | L2: MustNotDDE | M2: NoLink | P2: 32521 | Q2: 0
A3: SV | B3: 2 | C3: Visit Date | D3: TRUE | E3: https://az-cn.mdsol.com/MedidataRave/Help/Modules/Helpfile/D8318N00001_eCRF_Completion_Guidelines.pdf | F3: FALSE | G3: TRUE | H3: FALSE | J3: Site Monitor | L3: MustNotDDE | M3: NoLink | P3: 32522 | Q3: 0
A4: UNSCH | B4: 3 | C4: Unscheduled Forms | D4: TRUE | E4: https://az-cn.mdsol.com/MedidataRave/Help/Modules/Helpfile/D8318N00001_eCRF_Completion_Guidelines.pdf | F4: FALSE | G4: TRUE | H4: FALSE | J4: Site Monitor | L4: MustNotDDE | M4: NoLink | P4: 32608 | Q4: 0
A5: DS1_IC | B5: 4 | C5: Informed Consent | D5: TRUE | E5: https://az-cn.mdsol.com/MedidataRave/Help/Modules/Helpfile/D8318N00001_eCRF_Completion_Guidelines.pdf | F5: FALSE | G5: TRUE | H5: FALSE | J5: Site Monitor | K5: Landscape | L5: MustNotDDE | M5: NoLink | P5: 32523 | Q5: 0
A6: DM | B6: 5 | C6: Demographics | D6: TRUE | E6: https://az-cn.mdsol.com/MedidataRave/Help/Modules/Helpfile/D8318N00001_eCRF_Completion_Guidelines.pdf | F6: FALSE | G6: TRUE | H6: FALSE | J6: Site Monitor | L6: MustNotDDE | M6: NoLink | P6: 32524 | Q6: 0
A7: MH | B7: 6 | C7: Medical History | D7: TRUE | E7: https://az-cn.mdsol.com/MedidataRave/Help/Modules/Helpfile/D8318N00001_eCRF_Completion_Guidelines.pdf | F7: FALSE | G7: TRUE | H7: FALSE | J7: Site Monitor | K7: Landscape | L7: MustNotDDE | M7: NoLink | P7: 32525 | Q7: 0
A8: CM1 | B8: 7 | C8: IIM/SSc Medications Assessment | D8: TRUE | E8: https://az-cn.mdsol.com/MedidataRave/Help/Modules/Helpfile/D8318N00001_eCRF_Completion_Guidelines.pdf | F8: FALSE | G8: TRUE | H8: FALSE | J8: Site Monitor | K8: Landscape | L8: MustNotDDE | M8: NoLink | P8: 32622 | Q8: 0
A9: PR2 | B9: 8 | C9: IIM/SSc Procedures | D9: TRUE | E9: https://az-cn.mdsol.com/MedidataRave/Help/Modules/Helpfile/D8318N00001_eCRF_Completion_Guidelines.pdf | F9: FALSE | G9: TRUE | H9: FALSE | J9: Site Monitor | K9: Landscape | L9: MustNotDDE | M9: NoLink | P9: 32623 | Q9: 0
A10: SU | B10: 9 | C10: Allergy History | D10: TRUE | E10: https://az-cn.mdsol.com/MedidataRave/Help/Modules/Helpfile/D8318N00001_eCRF_Completion_Guidelines.pdf | F10: FALSE | G10: TRUE | H10: FALSE | J10: Site Monitor | K10: Landscape | L10: MustNotDDE | M10: NoLink | P10: 32526 | Q10: 0
A11: PR1 | B11: 10 | C11: Surgical History | D11: TRUE | E11: https://az-cn.mdsol.com/MedidataRave/Help/Modules/Helpfile/D8318N00001_eCRF_Completion_Guidelines.pdf | F11: FALSE | G11: TRUE | H11: FALSE | J11: Site Monitor | K11: Landscape | L11: MustNotDDE | M11: NoLink | P11: 32527 | Q11: 0
A12: HEI | B12: 11 | C12: Height | D12: TRUE | E12: https://az-cn.mdsol.com/MedidataRave/Help/Modules/Helpfile/D8318N00001_eCRF_Completion_Guidelines.pdf | F12: FALSE | G12: TRUE | H12: FALSE | J12: Site Monitor | L12: MustNotDDE | M12: NoLink | P12: 32528 | Q12: 0
A13: WEI | B13: 12 | C13: Weight | D13: TRUE | E13: https://az-cn.mdsol.com/MedidataRave/Help/Modules/Helpfile/D8318N00001_eCRF_Completion_Guidelines.pdf | F13: FALSE | G13: TRUE | H13: FALSE | J13: Site Monitor | L13: MustNotDDE | M13: NoLink | P13: 32529 | Q13: 0
A14: CV1 | B14: 13 | C14: Chest X-ray | D14: TRUE | E14: https://az-cn.mdsol.com/MedidataRave/Help/Modules/Helpfile/D8318N00001_eCRF_Completion_Guidelines.pdf | F14: FALSE | G14: TRUE | H14: FALSE | J14: Site Monitor | L14: MustNotDDE | M14: NoLink | P14: 32530 | Q14: 0
A15: CV2 | B15: 14 | C15: Chest CT | D15: TRUE | E15: https://az-cn.mdsol.com/MedidataRave/Help/Modules/Helpfile/D8318N00001_eCRF_Completion_Guidelines.pdf | F15: FALSE | G15: TRUE | H15: FALSE | J15: Site Monitor | L15: MustNotDDE | M15: NoLink | P15: 32531 | Q15: 0
A16: CV4 | B16: 15 | C16: Chest HRCT | D16: TRUE | E16: https://az-cn.mdsol.com/MedidataRave/Help/Modules/Helpfile/D8318N00001_eCRF_Completion_Guidelines.pdf | F16: FALSE | G16: TRUE | H16: FALSE | J16: Site Monitor | L16: MustNotDDE | M16: NoLink | P16: 32532 | Q16: 0
A17: CV5 | B17: 16 | C17: Muscle MRI | D17: TRUE | E17: https://az-cn.mdsol.com/MedidataRave/Help/Modules/Helpfile/D8318N00001_eCRF_Completion_Guidelines.pdf | F17: FALSE | G17: TRUE | H17: FALSE | J17: Site Monitor | L17: MustNotDDE | M17: NoLink | P17: 32533 | Q17: 0
A18: CV3 | B18: 17 | C18: FAPI PET/CT | D18: TRUE | E18: https://az-cn.mdsol.com/MedidataRave/Help/Modules/Helpfile/D8318N00001_eCRF_Completion_Guidelines.pdf | F18: FALSE | G18: TRUE | H18: FALSE | J18: Site Monitor | L18: MustNotDDE | M18: NoLink | P18: 32534 | Q18: 0
A19: MK6 | B19: 18 | C19: Muscle biopsy pathology | D19: TRUE | E19: https://az-cn.mdsol.com/MedidataRave/Help/Modules/Helpfile/D8318N00001_eCRF_Completion_Guidelines.pdf | F19: FALSE | G19: TRUE | H19: FALSE | J19: Site Monitor | L19: MustNotDDE | M19: NoLink | P19: 32535 | Q19: 0
A20: MK7 | B20: 19 | C20: Skin biopsy pathology | D20: TRUE | E20: https://az-cn.mdsol.com/MedidataRave/Help/Modules/Helpfile/D8318N00001_eCRF_Completion_Guidelines.pdf | F20: FALSE | G20: TRUE | H20: FALSE | J20: Site Monitor | L20: MustNotDDE | M20: NoLink | P20: 32536 | Q20: 0
A21: EG1 | B21: 20 | C21: Electrocardiogram | D21: TRUE | E21: https://az-cn.mdsol.com/MedidataRave/Help/Modules/Helpfile/D8318N00001_eCRF_Completion_Guidelines.pdf | F21: FALSE | G21: TRUE | H21: FALSE | J21: Site Monitor | L21: MustNotDDE | M21: NoLink | P21: 32537 | Q21: 0
A22: ECHO | B22: 21 | C22: Echocardiogram | D22: TRUE | E22: https://az-cn.mdsol.com/MedidataRave/Help/Modules/Helpfile/D8318N00001_eCRF_Completion_Guidelines.pdf | F22: FALSE | G22: TRUE | H22: FALSE | J22: Site Monitor | L22: MustNotDDE | M22: NoLink | P22: 32538 | Q22: 0
A23: SR | B23: 22 | C23: Ultrasound elastography of skin | D23: TRUE | E23: https://az-cn.mdsol.com/MedidataRave/Help/Modules/Helpfile/D8318N00001_eCRF_Completion_Guidelines.pdf | F23: FALSE | G23: TRUE | H23: FALSE | J23: Site Monitor | L23: MustNotDDE | M23: NoLink | P23: 32539 | Q23: 0
... A25: VS1 | B25: 24 | C25: Vital Signs-1 | D25: TRUE | E25: https://az-cn.mdsol.com/MedidataRave/Help/Modules/Helpfile/D8318N00001_eCRF_Completion_Guidelines.pdf | F25: FALSE | G25: TRUE | H25: FALSE | J25: Site Monitor | L25: MustNotDDE | M25: NoLink | P25: 32541 | Q25: 0
A26: VS2 | B26: 25 | C26: Vital Signs-2 | D26: TRUE | E26: https://az-cn.mdsol.com/MedidataRave/Help/Modules/Helpfile/D8318N00001_eCRF_Completion_Guidelines.pdf | F26: FALSE | G26: TRUE | H26: FALSE | J26: Site Monitor | K26: Landscape | L26: MustNotDDE | M26: NoLink | P26: 32542 | Q26: 0
A27: PE | B27: 26 | C27: Physical Examination | D27: TRUE | E27: https://az-cn.mdsol.com/MedidataRave/Help/Modules/Helpfile/D8318N00001_eCRF_Completion_Guidelines.pdf | F27: FALSE | G27: TRUE | H27: FALSE | J27: Site Monitor | K27: Landscape | L27: MustNotDDE | M27: NoLink | P27: 32543 | Q27: 0
A28: RE | B28: 27 | C28: Pulmonary function tests | D28: TRUE | E28: https://az-cn.mdsol.com/MedidataRave/Help/Modules/Helpfile/D8318N00001_eCRF_Completion_Guidelines.pdf | F28: FALSE | G28: TRUE | H28: FALSE | J28: Site Monitor | K28: Landscape | L28: MustNotDDE | M28: NoLink | P28: 32544 | Q28: 0
A29: LB8_RP | B29: 28 | C29: Pregnancy Test | D29: TRUE | E29: https://az-cn.mdsol.com/MedidataRave/Help/Modules/Helpfile/D8318N00001_eCRF_Completion_Guidelines.pdf | F29: FALSE | G29: TRUE | H29: FALSE | J29: Site Monitor | L29: MustNotDDE | M29: NoLink | P29: 32545 | Q29: 0
A30: LB9_PAT | B30: 29 | C30: IIM Pathogenic antibodies | D30: TRUE | E30: https://az-cn.mdsol.com/MedidataRave/Help/Modules/Helpfile/D8318N00001_eCRF_Completion_Guidelines.pdf | F30: FALSE | G30: TRUE | H30: FALSE | J30: Site Monitor | L30: MustNotDDE | M30: NoLink | P30: 32546 | Q30: 0
A31: LB13_VAC | B31: 30 | C31: Vaccine Antibody Test | D31: TRUE | E31: https://az-cn.mdsol.com/MedidataRave/Help/Modules/Helpfile/D8318N00001_eCRF_Completion_Guidelines.pdf | F31: FALSE | G31: TRUE | H31: FALSE | J31: Site Monitor | L31: MustNotDDE | M31: NoLink | P31: 32547 | Q31: 0
A32: LB14_SER | B32: 31 | C32: Serum SSc-specific autoantibodies | D32: TRUE | E32: https://az-cn.mdsol.com/MedidataRave/Help/Modules/Helpfile/D8318N00001_eCRF_Completion_Guidelines.pdf | F32: FALSE | G32: TRUE | H32: FALSE | J32: Site Monitor | L32: MustNotDDE | M32: NoLink | P32: 32548 | Q32: 0
A33: LB19_SYP | B33: 32 | C33: Syphilis screening | D33: TRUE | E33: https://az-cn.mdsol.com/MedidataRave/Help/Modules/Helpfile/D8318N00001_eCRF_Completion_Guidelines.pdf | F33: FALSE | G33: TRUE | H33: FALSE | J33: Site Monitor | L33: MustNotDDE | M33: NoLink | P33: 32618 | Q33: 0
A34: LB16_VIR | B34: 33 | C34: Viral markers | D34: TRUE | E34: https://az-cn.mdsol.com/MedidataRave/Help/Modules/Helpfile/D8318N00001_eCRF_Completion_Guidelines.pdf | F34: FALSE | G34: TRUE | H34: FALSE | J34: Site Monitor | K34: Landscape | L34: MustNotDDE | M34: NoLink | P34: 32615 | Q34: 0
A35: LB17_HCV | B35: 34 | C35: HCV-RNA | D35: TRUE | E35: https://az-cn.mdsol.com/MedidataRave/Help/Modules/Helpfile/D8318N00001_eCRF_Completion_Guidelines.pdf | F35: FALSE | G35: TRUE | H35: FALSE | J35: Site Monitor | L35: MustNotDDE | M35: NoLink | P35: 32616 | Q35: 0
A36: LB18_HBV | B36: 35 | C36: HBV-DNA | D36: TRUE | E36: https://az-cn.mdsol.com/MedidataRave/Help/Modules/Helpfile/D8318N00001_eCRF_Completion_Guidelines.pdf | F36: FALSE | G36: TRUE | H36: FALSE | J36: Site Monitor | L36: MustNotDDE | M36: NoLink | P36: 32617 | Q36: 0
A37: LB10_ESR | B37: 36 | C37: ESR | D37: TRUE | E37: https://az-cn.mdsol.com/MedidataRave/Help/Modules/Helpfile/D8318N00001_eCRF_Completion_Guidelines.pdf | F37: FALSE | G37: TRUE | H37: FALSE | J37: Site Monitor | L37: MustNotDDE | M37: NoLink | P37: 32553 | Q37: 0
A38: LB11_HC | B38: 37 | C38: High-sensitivity C-reactive protein | D38: TRUE | E38: https://az-cn.mdsol.com/MedidataRave/Help/Modules/Helpfile/D8318N00001_eCRF_Completion_Guidelines.pdf | F38: FALSE | G38: TRUE | H38: FALSE | J38: Site Monitor | L38: MustNotDDE | M38: NoLink | P38: 32554 | Q38: 0
A39: LB12_TUB | B39: 38 | C39: Tuberculosis screening | D39: TRUE | E39: https://az-cn.mdsol.com/MedidataRave/Help/Modules/Helpfile/D8318N00001_eCRF_Completion_Guidelines.pdf | F39: FALSE | G39: TRUE | H39: FALSE | J39: Site Monitor | L39: MustNotDDE | M39: NoLink | P39: 32555 | Q39: 0
A40: LB1_HEM | B40: 39 | C40: Hematology | D40: TRUE | E40: https://az-cn.mdsol.com/MedidataRave/Help/Modules/Helpfile/D8318N00001_eCRF_Completion_Guidelines.pdf | F40: FALSE | G40: TRUE | H40: FALSE | J40: Site Monitor | L40: MustNotDDE | M40: NoLink | P40: 32556 | Q40: 0
A41: LB2_BLO | B41: 40 | C41: Blood chemistry | D41: TRUE | E41: https://az-cn.mdsol.com/MedidataRave/Help/Modules/Helpfile/D8318N00001_eCRF_Completion_Guidelines.pdf | F41: FALSE | G41: TRUE | H41: FALSE | J41: Site Monitor | L41: MustNotDDE | M41: NoLink | P41: 32557 | Q41: 0
...

Sheet Fields
A1: FormOID | B1: FieldOID | C1: Ordinal | D1: DraftFieldNumber | E1: DraftFieldName | F1: DraftFieldActive | G1: VariableOID | H1: DataFormat | I1: DataDictionaryName | J1: UnitDictionaryName | K1: CodingDictionary | L1: ControlType | M1: AcceptableFileExtensions | N1: IndentLevel | O1: PreText | P1: FixedUnit | Q1: HeaderText | R1: HelpText | S1: SourceDocument | T1: IsLog | U1: DefaultValue | V1: SASLabel | W1: SASFormat | X1: EproFormat | Y1: IsRequired | Z1: QueryFutureDate | AA1: IsVisible | AB1: IsTranslationRequired | AC1: AnalyteName | AD1: IsClinicalSignificance | AE1: QueryNonConformance | AF1: OtherVisits | AG1: CanSetRecordDate | AH1: CanSetDataPageDate | AI1: CanSetInstanceDate | AJ1: CanSetSubjectDate | AK1: DoesNotBreakSignature | AL1: LowerRange | AM1: UpperRange | AN1: NCLowerRange | AO1: NCUpperRange | AP1: ViewRestrictions | AQ1: EntryRestrictions | AR1: ReviewGroups | AS1: IsVisualVerify | AT1: FDownloadedFromObjectId | AU1: FSourceObjectId | AV1: VDownloadedFromObjectId | AW1: VSourceObjectId | AX1: FSourceUrlId | AY1: VSourceUrlId
A2: SC | B2: SITENUM | C2: 1 | E2: SITENUM | F2: TRUE | G2: SITENUM | H2: $2 | L2: Text | N2: 0 | O2: Site Identifier(Derived) | S2: FALSE | T2: FALSE | V2: Site Identifier(Derived) | Y2: FALSE | Z2: FALSE | AA2: TRUE | AB2: FALSE | AD2: FALSE | AE2: FALSE | AF2: FALSE | AG2: FALSE | AH2: FALSE | AI2: FALSE | AJ2: FALSE | AK2: FALSE | AQ2: Adjudicator,Agency Inspector,AZ Read Only,AZ Review and Query,Batch Upload,Coder,Coder Import Role,Data Manager,External Read Only,Investigator,Investigator - IVRS,Medical Monitor,Medidata Read Only,OL Role,Rave Imaging Integration,RSG Case Handler,SAE Administrator,SAE Case Handler,Site Coordinator,Site Coordinator - IVRS,Site Monitor,Study Developer | AS2: FALSE | AT2: 404969 | AU2: 0 | AV2: 271575 | AW2: 0
A3: SC | B3: SUBJNUM | C3: 2 | E3: SUBJNUM | F3: TRUE | G3: SUBJNUM | H3: 3+ | L3: Text | N3: 0 | O3: Participant Screening Sequence Identifier | S3: TRUE | T3: FALSE | V3: Participant Screening Sequence Identifier | Y3: TRUE | Z3: FALSE | AA3: TRUE | AB3: FALSE | AD3: FALSE | AE3: TRUE | AF3: FALSE | AG3: FALSE | AH3: FALSE | AI3: FALSE | AJ3: FALSE | AK3: FALSE | AR3: Data Manager | AS3: FALSE | AT3: 404971 | AU3: 0 | AV3: 271576 | AW3: 0
A4: SC | B4: SUBJID | C4: 3 | E4: SUBJID | F4: TRUE | G4: SUBJID | H4: $8 | L4: Text | N4: 0 | O4: Participant ID(Derived) | S4: FALSE | T4: FALSE | V4: Participant ID(Derived) | Y4: FALSE | Z4: FALSE | AA4: TRUE | AB4: FALSE | AD4: FALSE | AE4: FALSE | AF4: FALSE | AG4: FALSE | AH4: FALSE | AI4: FALSE | AJ4: FALSE | AK4: FALSE | AQ4: Adjudicator,Agency Inspector,AZ Read Only,AZ Review and Query,Batch Upload,Coder,Coder Import Role,Data Manager,External Read Only,Investigator,Investigator - IVRS,Medical Monitor,Medidata Read Only,OL Role,Rave Imaging Integration,RSG Case Handler,SAE Administrator,SAE Case Handler,Site Coordinator,Site Coordinator - IVRS,Site Monitor,Study Developer | AS4: FALSE | AT4: 404970 | AU4: 0 | AV4: 271577 | AW4: 0
A5: SC | B5: INDTYP | C5: 4 | E5: INDTYP | F5: TRUE | G5: INDTYP | H5: 2 | I5: Indication | L5: RadioButton | N5: 0 | O5: Indication | S5: TRUE | T5: FALSE | V5: Indication | Y5: TRUE | Z5: FALSE | AA5: TRUE | AB5: FALSE | AD5: FALSE | AE5: TRUE | AF5: FALSE | AG5: FALSE | AH5: FALSE | AI5: FALSE | AJ5: FALSE | AK5: FALSE | AR5: Data Manager | AS5: FALSE | AT5: 404968 | AU5: 0 | AV5: 271578 | AW5: 0
A6: SV | B6: VISDAT | C6: 1 | E6: VISDAT | F6: TRUE | G6: VISDAT | H6: yyyy/mm/dd | L6: DateTime | N6: 0 | O6: Visit Date | S6: TRUE | T6: FALSE | V6: Visit Date | Y6: FALSE | Z6: TRUE | AA6: TRUE | AB6: FALSE | AD6: FALSE | AE6: TRUE | AF6: FALSE | AG6: FALSE | AH6: FALSE | AI6: FALSE | AJ6: FALSE | AK6: FALSE | AR6: Data Manager | AS6: FALSE | AT6: 403791 | AU6: 0 | AV6: 271579 | AW6: 0
A7: SV | B7: SVSTAT | C7: 2 | E7: SVSTAT | F7: TRUE | G7: SVSTAT | H7: 2 | I7: Yes | L7: RadioButton | N7: 0 | O7: Visit Not Done | S7: TRUE | T7: FALSE | V7: Visit Not Done | Y7: FALSE | Z7: FALSE | AA7: TRUE | AB7: FALSE | AD7: FALSE | AE7: TRUE | AF7: FALSE | AG7: FALSE | AH7: FALSE | AI7: FALSE | AJ7: FALSE | AK7: FALSE | AR7: Data Manager | AS7: FALSE | AT7: 403790 | AU7: 0 | AV7: 271580 | AW7: 0
A8: SV | B8: SVRSND | C8: 3 | E8: SVRSND | F8: TRUE | G8: SVRSND | H8: $200 | L8: LongText | N8: 0 | O8: If not done, please specify the reason | S8: TRUE | T8: FALSE | V8: If not done, please specify the reason | Y8: TRUE | Z8: FALSE | AA8: FALSE | AB8: FALSE | AD8: FALSE | AE8: TRUE | AF8: FALSE | AG8: FALSE | AH8: FALSE | AI8: FALSE | AJ8: FALSE | AK8: FALSE | AR8: Data Manager | AS8: FALSE | AT8: 403789 | AU8: 0 | AV8: 271581 | AW8: 0
A9: UNSCH | B9: UNSHEI | C9: 1 | E9: UNSHEI | F9: TRUE | G9: UNSHEI | H9: 2 | I9: Yes | L9: RadioButton | N9: 0 | O9: Height | S9: TRUE | T9: FALSE | V9: Height | Y9: FALSE | Z9: FALSE | AA9: TRUE | AB9: FALSE | AD9: FALSE | AE9: TRUE | AF9: FALSE | AG9: FALSE | AH9: FALSE | AI9: FALSE | AJ9: FALSE | AK9: FALSE | AR9: Data Manager | AS9: FALSE | AT9: 404796 | AU9: 0 | AV9: 272347 | AW9: 0
A10: UNSCH | B10: UNSWEI | C10: 2 | E10: UNSWEI | F10: TRUE | G10: UNSWEI | H10: 2 | I10: Yes | L10: RadioButton | N10: 0 | O10: Weight | S10: TRUE | T10: FALSE | V10: Weight | Y10: FALSE | Z10: FALSE | AA10: TRUE | AB10: FALSE | AD10: FALSE | AE10: TRUE | AF10: FALSE | AG10: FALSE | AH10: FALSE | AI10: FALSE | AJ10: FALSE | AK10: FALSE | AR10: Data Manager | AS10: FALSE | AT10: 404833 | AU10: 0 | AV10: 272348 | AW10: 0
A11: UNSCH | B11: UNSCV1 | C11: 3 | E11: UNSCV1 | F11: TRUE | G11: UNSCV1 | H11: 2 | I11: Yes | L11: RadioButton | N11: 0 | O11: Chest X-ray | S11: TRUE | T11: FALSE | V11: Chest X-ray | Y11: FALSE | Z11: FALSE | AA11: TRUE | AB11: FALSE | AD11: FALSE | AE11: TRUE | AF11: FALSE | AG11: FALSE | AH11: FALSE | AI11: FALSE | AJ11: FALSE | AK11: FALSE | AR11: Data Manager | AS11: FALSE | AT11: 404782 | AU11: 0 | AV11: 272399 | AW11: 0
A12: UNSCH | B12: UNSCV2 | C12: 4 | E12: UNSCV2 | F12: TRUE | G12: UNSCV2 | H12: 2 | I12: Yes | L12: RadioButton | N12: 0 | O12: Chest CT | S12: TRUE | T12: FALSE | V12: Chest CT | Y12: FALSE | Z12: FALSE | AA12: TRUE | AB12: FALSE | AD12: FALSE | AE12: TRUE | AF12: FALSE | AG12: FALSE | AH12: FALSE | AI12: FALSE | AJ12: FALSE | AK12: FALSE | AR12: Data Manager | AS12: FALSE | AT12: 404783 | AU12: 0 | AV12: 272585 | AW12: 0
A13: UNSCH | B13: UNSCV4 | C13: 5 | E13: UNSCV4 | F13: TRUE | G13: UNSCV4 | H13: 2 | I13: Yes | L13: RadioButton | N13: 0 | O13: Chest HRCT | S13: TRUE | T13: FALSE | V13: Chest HRCT | Y13: FALSE | Z13: FALSE | AA13: TRUE | AB13: FALSE | AD13: FALSE | AE13: TRUE | AF13: FALSE | AG13: FALSE | AH13: FALSE | AI13: FALSE | AJ13: FALSE | AK13: FALSE | AR13: Data Manager | AS13: FALSE | AT13: 404785 | AU13: 0 | AV13: 272586 | AW13: 0
A14: UNSCH | B14: UNSCV5 | C14: 6 | E14: UNSCV5 | F14: TRUE | G14: UNSCV5 | H14: 2 | I14: Yes | L14: RadioButton | N14: 0 | O14: Muscle MRI | S14: TRUE | T14: FALSE | V14: Muscle MRI | Y14: FALSE | Z14: FALSE | AA14: TRUE | AB14: FALSE | AD14: FALSE | AE14: TRUE | AF14: FALSE | AG14: FALSE | AH14: FALSE | AI14: FALSE | AJ14: FALSE | AK14: FALSE | AR14: Data Manager | AS14: FALSE | AT14: 404786 | AU14: 0 | AV14: 272587 | AW14: 0
A15: UNSCH | B15: UNSCV3 | C15: 7 | E15: UNSCV3 | F15: TRUE | G15: UNSCV3 | H15: 2 | I15: Yes | L15: RadioButton | N15: 0 | O15: FAPI PET/CT | S15: TRUE | T15: FALSE | V15: FAPI PET/CT | Y15: FALSE | Z15: FALSE | AA15: TRUE | AB15: FALSE | AD15: FALSE | AE15: TRUE | AF15: FALSE | AG15: FALSE | AH15: FALSE | AI15: FALSE | AJ15: FALSE | AK15: FALSE | AR15: Data Manager | AS15: FALSE | AT15: 404784 | AU15: 0 | AV15: 272588 | AW15: 0
A16: UNSCH | B16: UNSMK6 | C16: 8 | E16: UNSMK6 | F16: TRUE | G16: UNSMK6 | H16: 2 | I16: Yes | L16: RadioButton | N16: 0 | O16: Muscle biopsy pathology | S16: TRUE | T16: FALSE | V16: Muscle biopsy pathology | Y16: FALSE | Z16: FALSE | AA16: TRUE | AB16: FALSE | AD16: FALSE | AE16: TRUE | AF16: FALSE | AG16: FALSE | AH16: FALSE | AI16: FALSE | AJ16: FALSE | AK16: FALSE | AR16: Data Manager | AS16: FALSE | AT16: 404822 | AU16: 0 | AV16: 272589 | AW16: 0
A17: UNSCH | B17: UNSMK7 | C17: 9 | E17: UNSMK7 | F17: TRUE | G17: UNSMK7 | H17: 2 | I17: Yes | L17: RadioButton | N17: 0 | O17: Skin biopsy pathology | S17: TRUE | T17: FALSE | V17: Skin biopsy pathology | Y17: FALSE | Z17: FALSE | AA17: TRUE | AB17: FALSE | AD17: FALSE | AE17: TRUE | AF17: FALSE | AG17: FALSE | AH17: FALSE | AI17: FALSE | AJ17: FALSE | AK17: FALSE | AR17: Data Manager | AS17: FALSE | AT17: 404823 | AU17: 0 | AV17: 272590 | AW17: 0
A18: UNSCH | B18: UNSEG1 | C18: 10 | E18: UNSEG1 | F18: TRUE | G18: UNSEG1 | H18: 2 | I18: Yes | L18: RadioButton | N18: 0 | O18: Electrocardiogram | S18: TRUE | T18: FALSE | V18: Electrocardiogram | Y18: FALSE | Z18: FALSE | AA18: TRUE | AB18: FALSE | AD18: FALSE | AE18: TRUE | AF18: FALSE | AG18: FALSE | AH18: FALSE | AI18: FALSE | AJ18: FALSE | AK18: FALSE | AR18: Data Manager | AS18: FALSE | AT18: 404790 | AU18: 0 | AV18: 272351 | AW18: 0
A19: UNSCH | B19: UNSECHO | C19: 11 | E19: UNSECHO | F19: TRUE | G19: UNSECHO | H19: 2 | I19: Yes | L19: RadioButton | N19: 0 | O19: Echocardiogram | S19: TRUE | T19: FALSE | V19: Echocardiogram | Y19: FALSE | Z19: FALSE | AA19: TRUE | AB19: FALSE | AD19: FALSE | AE19: TRUE | AF19: FALSE | AG19: FALSE | AH19: FALSE | AI19: FALSE | AJ19: FALSE | AK19: FALSE | AR19: Data Manager | AS19: FALSE | AT19: 404789 | AU19: 0 | AV19: 272352 | AW19: 0
A20: UNSCH | B20: UNSSR | C20: 12 | E20: UNSSR | F20: TRUE | G20: UNSSR | H20: 2 | I20: Yes | L20: RadioButton | N20: 0 | O20: Ultrasound elastography of skin | S20: TRUE | T20: FALSE | V20: Ultrasound elastography of skin | Y20: FALSE | Z20: FALSE | AA20: TRUE | AB20: FALSE | AD20: FALSE | AE20: TRUE | AF20: FALSE | AG20: FALSE | AH20: FALSE | AI20: FALSE | AJ20: FALSE | AK20: FALSE | AR20: Data Manager | AS20: FALSE | AT20: 404831 | AU20: 0 | AV20: 272591 | AW20: 0
... A67: UNSCH | B67: UNSFA | C67: 59 | E67: UNSFA | F67: TRUE | G67: UNSFA | H67: 2 | I67: Yes | L67: RadioButton | N67: 0 | O67: Other Test | S67: TRUE | T67: FALSE | V67: Other Test | Y67: FALSE | Z67: FALSE | AA67: TRUE | AB67: FALSE | AD67: FALSE | AE67: TRUE | AF67: FALSE | AG67: FALSE | AH67: FALSE | AI67: FALSE | AJ67: FALSE | AK67: FALSE | AR67: Data Manager | AS67: FALSE | AT67: 404792 | AU67: 0 | AV67: 272410 | AW67: 0
A68: UNSCH | B68: UNSMI | C68: 60 | E68: UNSMI | F68: FALSE | G68: UNSMI | H68: 2 | I68: Yes | L68: RadioButton | N68: 0 | O68: Collection of mononuclear cells | S68: FALSE | T68: FALSE | V68: Collection of mononuclear cells | Y68: FALSE | Z68: FALSE | AA68: TRUE | AB68: FALSE | AD68: FALSE | AE68: FALSE | AF68: FALSE | AG68: FALSE | AH68: FALSE | AI68: FALSE | AJ68: FALSE | AK68: FALSE | AS68: FALSE | AT68: 404816 | AU68: 0 | AV68: 272337 | AW68: 0
A69: UNSCH | B69: UNSEC1 | C69: 61 | E69: UNSEC1 | F69: FALSE | G69: UNSEC1 | H69: 2 | I69: Yes | L69: RadioButton | N69: 0 | O69: Lymphodepletion pretreatment | S69: FALSE | T69: FALSE | V69: Lymphodepletion pretreatment | Y69: FALSE | Z69: FALSE | AA69: TRUE | AB69: FALSE | AD69: FALSE | AE69: FALSE | AF69: FALSE | AG69: FALSE | AH69: FALSE | AI69: FALSE | AJ69: FALSE | AK69: FALSE | AS69: FALSE | AT69: 404787 | AU69: 0 | AV69: 272338 | AW69: 0
A70: UNSCH | B70: UNSEC2 | C70: 62 | E70: UNSEC2 | F70: FALSE | G70: UNSEC2 | H70: 2 | I70: Yes | L70: RadioButton | N70: 0 | O70: GC012F Injection infusion | S70: FALSE | T70: FALSE | V70: GC012F Injection infusion | Y70: FALSE | Z70: FALSE | AA70: TRUE | AB70: FALSE | AD70: FALSE | AE70: FALSE | AF70: FALSE | AG70: FALSE | AH70: FALSE | AI70: FALSE | AJ70: FALSE | AK70: FALSE | AS70: FALSE | AT70: 404788 | AU70: 0 | AV70: 272339 | AW70: 0
A71: UNSCH | B71: UNSCP1 | C71: 63 | E71: UNSCP1 | F71: FALSE | G71: UNSCP1 | H71: 2 | I71: Yes | L71: RadioButton | N71: 0 | O71: Syphilis screening | S71: FALSE | T71: FALSE | V71: Syphilis screening | Y71: FALSE | Z71: FALSE | AA71: FALSE | AB71: FALSE | AD71: FALSE | AE71: FALSE | AF71: FALSE | AG71: FALSE | AH71: FALSE | AI71: FALSE | AJ71: FALSE | AK71: FALSE | AS71: FALSE | AT71: 404767 | AU71: 0 | AV71: 272340 | AW71: 0
A72: UNSCH | B72: UNSCP2 | C72: 64 | E72: UNSCP2 | F72: FALSE | G72: UNSCP2 | H72: 2 | I72: Yes | L72: RadioButton | N72: 0 | O72: Viral markers | S72: TRUE | T72: FALSE | V72: Viral markers | Y72: FALSE | Z72: FALSE | AA72: FALSE | AB72: FALSE | AD72: FALSE | AE72: FALSE | AF72: FALSE | AG72: FALSE | AH72: FALSE | AI72: FALSE | AJ72: FALSE | AK72: FALSE | AR72: Data Manager | AS72: FALSE | AT72: 404774 | AU72: 0 | AV72: 272400 | AW72: 0
A73: UNSCH | B73: UNSCP3 | C73: 65 | E73: UNSCP3 | F73: FALSE | G73: UNSCP3 | H73: 2 | I73: Yes | L73: RadioButton | N73: 0 | O73: HCV-RNA | S73: FALSE | T73: FALSE | V73: HCV-RNA | Y73: FALSE | Z73: FALSE | AA73: FALSE | AB73: FALSE | AD73: FALSE | AE73: FALSE | AF73: FALSE | AG73: FALSE | AH73: FALSE | AI73: FALSE | AJ73: FALSE | AK73: FALSE | AS73: FALSE | AT73: 404775 | AU73: 0 | AV73: 272356 | AW73: 0
A74: UNSCH | B74: UNSCP4 | C74: 66 | E74: UNSCP4 | F74: FALSE | G74: UNSCP4 | H74: 2 | I74: Yes | L74: RadioButton | N74: 0 | O74: HBV-DNA | S74: FALSE | T74: FALSE | V74: HBV-DNA | Y74: FALSE | Z74: FALSE | AA74: FALSE | AB74: FALSE | AD74: FALSE | AE74: FALSE | AF74: FALSE | AG74: FALSE | AH74: FALSE | AI74: FALSE | AJ74: FALSE | AK74: FALSE | AS74: FALSE | AT74: 404776 | AU74: 0 | AV74: 272367 | AW74: 0
A75: UNSCH | B75: UNSCP17 | C75: 67 | E75: UNSCP17 | F75: FALSE | G75: UNSCP17 | H75: 2 | I75: Yes | L75: RadioButton | N75: 0 | O75: Aldolase Testing | S75: FALSE | T75: FALSE | V75: Aldolase Testing | Y75: FALSE | Z75: FALSE | AA75: TRUE | AB75: FALSE | AD75: FALSE | AE75: FALSE | AF75: FALSE | AG75: FALSE | AH75: FALSE | AI75: FALSE | AJ75: FALSE | AK75: FALSE | AS75: FALSE | AT75: 404773 | AU75: 0 | AV75: 272543 | AW75: 0
A76: DS1_IC | B76: DS1YN | C76: 1 | E76: DS1YN | F76: TRUE | G76: DS1YN | H76: 2 | I76: YesNo | L76: RadioButton | N76: 0 | O76: Was Informed Consent Form signed? | S76: TRUE | T76: FALSE | V76: Was Informed Consent Form signed? | Y76: TRUE | Z76: FALSE | AA76: TRUE | AB76: FALSE | AD76: FALSE | AE76: TRUE | AF76: FALSE | AG76: FALSE | AH76: FALSE | AI76: FALSE | AJ76: FALSE | AK76: FALSE | AR76: Data Manager | AS76: FALSE | AT76: 403983 | AU76: 0 | AV76: 271582 | AW76: 0
A77: DS1_IC | B77: DS1REID | C77: 2 | E77: DS1REID | F77: TRUE | G77: DS1REID | H77: $8 | L77: Text | N77: 0 | O77: If re-screening, Previous Participant ID | S77: TRUE | T77: FALSE | V77: If re-screening, Previous Participant ID | Y77: TRUE | Z77: FALSE | AA77: TRUE | AB77: FALSE | AD77: FALSE | AE77: TRUE | AF77: FALSE | AG77: FALSE | AH77: FALSE | AI77: FALSE | AJ77: FALSE | AK77: FALSE | AR77: Data Manager | AS77: FALSE | AT77: 403978 | AU77: 0 | AV77: 271583 | AW77: 0
A78: DS1_IC | B78: DS1DAT | C78: 3 | E78: DS1DAT | F78: TRUE | G78: DS1DAT | H78: yyyy/mm/dd | L78: DateTime | N78: 0 | O78: First Informed Consent Signing Date | S78: TRUE | T78: FALSE | V78: First Informed Consent Signing Date | Y78: TRUE | Z78: TRUE | AA78: FALSE | AB78: FALSE | AD78: FALSE | AE78: TRUE | AF78: FALSE | AG78: FALSE | AH78: FALSE | AI78: FALSE | AJ78: FALSE | AK78: FALSE | AR78: Data Manager | AS78: FALSE | AT78: 403975 | AU78: 0 | AV78: 271584 | AW78: 0
A79: DS1_IC | B79: DS1VER1 | C79: 4 | E79: DS1VER1 | F79: TRUE | G79: DS1VER1 | H79: 2 | I79: IC Version1 | L79: DropDownList | N79: 0 | O79: Informed Consent No. | S79: TRUE | T79: FALSE | V79: Informed Consent No. | Y79: TRUE | Z79: FALSE | AA79: FALSE | AB79: FALSE | AD79: FALSE | AE79: TRUE | AF79: FALSE | AG79: FALSE | AH79: FALSE | AI79: FALSE | AJ79: FALSE | AK79: FALSE | AR79: Data Manager | AS79: FALSE | AT79: 403981 | AU79: 0 | AV79: 271585 | AW79: 0
A80: DS1_IC | B80: DS1VER2 | C80: 5 | E80: DS1VER2 | F80: TRUE | G80: DS1VER2 | H80: 2 | I80: IC Version2 | L80: DropDownList | N80: 0 | O80: Protocol Version No. | S80: TRUE | T80: FALSE | V80: Protocol Version No. | Y80: TRUE | Z80: FALSE | AA80: FALSE | AB80: FALSE | AD80: FALSE | AE80: TRUE | AF80: FALSE | AG80: FALSE | AH80: FALSE | AI80: FALSE | AJ80: FALSE | AK80: FALSE | AR80: Data Manager | AS80: FALSE | AT80: 403982 | AU80: 0 | AV80: 271586 | AW80: 0
A81: DS1_IC | B81: DS1LABEL | C81: 6 | E81: DS1LABEL | F81: TRUE | L81: Text | N81: 0 | O81: If the informed consent is re-signed, please complete the following information. | S81: FALSE | T81: FALSE | Y81: FALSE | Z81: FALSE | AA81: TRUE | AB81: FALSE | AD81: FALSE | AE81: FALSE | AF81: FALSE | AG81: FALSE | AH81: FALSE | AI81: FALSE | AJ81: FALSE | AK81: TRUE | AS81: FALSE | AT81: 403976 | AU81: 0
A82: DS1_IC | B82: DS1RDAT | C82: 7 | E82: DS1RDAT | F82: TRUE | G82: DS1RDAT | H82: yyyy/mm/dd | L82: DateTime | N82: 0 | O82: Informed Consent Date | S82: TRUE | T82: TRUE | V82: Informed Consent Date | Y82: FALSE | Z82: TRUE | AA82: TRUE | AB82: FALSE | AD82: FALSE | AE82: TRUE | AF82: FALSE | AG82: FALSE | AH82: FALSE | AI82: FALSE | AJ82: FALSE | AK82: FALSE | AR82: Data Manager | AS82: FALSE | AT82: 403977 | AU82: 0 | AV82: 271587 | AW82: 0
A83: DS1_IC | B83: DS1RVER1 | C83: 8 | E83: DS1RVER1 | F83: TRUE | G83: DS1RVER1 | H83: 2 | I83: IC Version1 | L83: DropDownList | N83: 0 | O83: Informed Consent No. | S83: TRUE | T83: TRUE | V83: Informed Consent No. | Y83: FALSE | Z83: FALSE | AA83: TRUE | AB83: FALSE | AD83: FALSE | AE83: TRUE | AF83: FALSE | AG83: FALSE | AH83: FALSE | AI83: FALSE | AJ83: FALSE | AK83: FALSE | AR83: Data Manager | AS83: FALSE | AT83: 403979 | AU83: 0 | AV83: 271588 | AW83: 0
A84: DS1_IC | B84: DS1RVER2 | C84: 9 | E84: DS1RVER2 | F84: TRUE | G84: DS1RVER2 | H84: 2 | I84: IC Version2 | L84: DropDownList | N84: 0 | O84: Protocol Version No. | S84: TRUE | T84: TRUE | V84: Protocol Version No. | Y84: FALSE | Z84: FALSE | AA84: TRUE | AB84: FALSE | AD84: FALSE | AE84: TRUE | AF84: FALSE | AG84: FALSE | AH84: FALSE | AI84: FALSE | AJ84: FALSE | AK84: FALSE | AR84: Data Manager | AS84: FALSE | AT84: 403980 | AU84: 0 | AV84: 271589 | AW84: 0
A85: DS1_IC | B85: CURRTIM | C85: 10 | E85: CURRTIM | F85: TRUE | G85: CURRTIM | H85: yyyy/mm/dd HH:nn:ss | L85: DateTime | N85: 0 | O85: Current Time (Derived) | S85: FALSE | T85: FALSE | V85: Current Time (Derived) | Y85: FALSE | Z85: FALSE | AA85: TRUE | AB85: FALSE | AD85: FALSE | AE85: FALSE | AF85: FALSE | AG85: FALSE | AH85: FALSE | AI85: FALSE | AJ85: FALSE | AK85: TRUE | AP85: Coder Import Role,Batch Upload,Rave Imaging Integration,OL Role,Site Coordinator - IVRS,Investigator - IVRS,Data Manager,AZ Read Only,Site Monitor,Coder,SAE Administrator,SAE Case Handler,RSG Case Handler,Study Developer,AZ Review and Query,Adjudicator,External Read Only,Agency Inspector,Site Coordinator,Investigator,Medidata Read Only,Medical Monitor | AQ85: Adjudicator,Agency Inspector,AZ Read Only,AZ Review and Query,Batch Upload,Coder,Coder Import Role,Data Manager,External Read Only,Investigator,Investigator - IVRS,Medical Monitor,Medidata Read Only,OL Role,Rave Imaging Integration,RSG Case Handler,SAE Administrator,SAE Case Handler,Site Coordinator,Site Coordinator - IVRS,Site Monitor,Study Developer | AS85: FALSE | AT85: 403974 | AU85: 0 | AV85: 271726 | AW85: 0
A86: DM | B86: BRTHDAT | C86: 1 | E86: BRTHDAT | F86: TRUE | G86: BRTHDAT | H86: yyyy | L86: DateTime | N86: 0 | O86: Date of Birth | S86: TRUE | T86: FALSE | V86: Date of Birth | Y86: TRUE | Z86: TRUE | AA86: TRUE | AB86: FALSE | AD86: FALSE | AE86: TRUE | AF86: FALSE | AG86: FALSE | AH86: FALSE | AI86: FALSE | AJ86: FALSE | AK86: FALSE | AR86: Data Manager | AS86: FALSE | AT86: 403987 | AU86: 0 | AV86: 271590 | AW86: 0
...

Sheet Folders
A1: OID | B1: Ordinal | C1: FolderName | D1: AccessDays | E1: StartWinDays | F1: Targetdays | G1: EndWinDays | H1: OverDueDays | I1: CloseDays | J1: ParentFolderOID | K1: IsReusable | L1: DownloadedFromObjectId | M1: SourceObjectId | N1: SourceUrlId
A2: BASE | B2: 4 | C2: Baseline Period | K2: FALSE | L2: 15190 | M2: 0
A3: COL1 | B3: 2 | C3: Apheresis collection Day | K3: FALSE | L3: 15191 | M3: 0
A4: COL2 | B4: 3 | C4: Second Apheresis collection Day | K4: FALSE | L4: 15192 | M4: 0
A5: EC1 | B5: 5 | C5: Lymphodepletion Pretreatment Period | K5: FALSE | L5: 15193 | M5: 0
A6: EC2 | B6: 6 | C6: GC012F Infusion | K6: FALSE | L6: 15194 | M6: 0
A7: EOS1 | B7: 27 | C7: End of Study Visit | K7: FALSE | L7: 15195 | M7: 0
A8: EOS2 | B8: 31 | C8: End of Study | K8: FALSE | L8: 15196 | M8: 0
A9: GF | B9: 29 | C9: General forms | K9: TRUE | L9: 15197 | M9: 0
A10: LFU1 | B10: 19 | C10: Long-term Follow-up (D840±14) | K10: FALSE | L10: 15198 | M10: 0
A11: LFU2 | B11: 20 | C11: Long-term Follow-up (D1008±14) | K11: FALSE | L11: 15199 | M11: 0
A12: LFU3 | B12: 21 | C12: Long-term Follow-up (D1176±14) | K12: FALSE | L12: 15200 | M12: 0
A13: LFU4 | B13: 22 | C13: Long-term Follow-up (D1344±14) | K13: FALSE | L13: 15201 | M13: 0
... A32: WS | B32: 26 | C32: Withdrawal Visit | K32: FALSE | L32: 15220 | M32: 0

Sheet DataDictionaries
A1: DataDictionaryName | B1: OID | C1: DownloadedFromObjectId | D1: SourceObjectId | E1: SourceUrlId
A2: adjustment1 | B2: ADJUSTMENT1 | C2: 56889 | D2: 0
A3: adjustment2 | B3: ADJUSTMENT2 | C3: 56890 | D3: 0
A4: AEACN1 | B4: AEACN1 | C4: 56891 | D4: 0
A5: AEACN2 | B5: AEACN2 | C5: 56892 | D5: 0
A6: AEOUT | B6: AEOUT | C6: 56893 | D6: 0
A7: AEREL | B7: AEREL | C7: 56894 | D7: 0
A8: AESI Type | B8: AESITYPE | C8: 56895 | D8: 0
A9: Allergy Type | B9: ALLERGYTYPE | C9: 56896 | D9: 0
A10: ASSESS1 | B10: ASSESS1 | C10: 56897 | D10: 0
A11: ASSESS2 | B11: ASSESS2 | C11: 56898 | D11: 0
A12: ASSESS3 | B12: ASSESS3 | C12: 56899 | D12: 0
A13: ASSESS4 | B13: ASSESS4 | C13: 56900 | D13: 0
... A88: YesNoNA | B88: YESNONA | C88: 56975 | D88: 0

Sheet DataDictionaryEntries
A1: DataDictionaryName | B1: CodedData | C1: Ordinal | D1: UserDataString | E1: Specify
A2: adjustment1 | B2: 1 | C2: 1 | D2: Dose Increased | E2: FALSE
A3: adjustment1 | B3: 2 | C3: 2 | D3: Dose Reduced | E3: FALSE
A4: adjustment1 | B4: 3 | C4: 3 | D4: Drug Interrupted | E4: FALSE
A5: adjustment1 | B5: 4 | C5: 4 | D5: Drug Permanently | E5: FALSE
A6: adjustment1 | B6: 5 | C6: 5 | D6: Discontinued | E6: FALSE
A7: adjustment2 | B7: 1 | C7: 1 | D7: Dose Increased | E7: FALSE
A8: adjustment2 | B8: 2 | C8: 2 | D8: Dose Reduced | E8: FALSE
A9: adjustment2 | B9: 3 | C9: 3 | D9: Drug Interrupted | E9: FALSE
A10: adjustment2 | B10: 4 | C10: 4 | D10: Drug Permanently Discontinued | E10: FALSE
A11: AEACN1 | B11: 1 | C11: 1 | D11: Dose Not Changed | E11: FALSE
A12: AEACN1 | B12: 2 | C12: 2 | D12: Dose Increased | E12: FALSE
... A489: YesNoNA | B489: 3 | C489: 3 | D489: NA | E489: FALSE

Sheet UnitDictionaries
A1: UnitDictionaryName | B1: StandardUnitName | C1: OID | D1: DownloadedFromObjectId | E1: SourceObjectId | F1: SourceUrlId

Sheet UnitDictionaryEntries
A1: UnitDictionaryName | B1: CodedUnit | C1: Ordinal | D1: ConstantA | E1: ConstantB | F1: ConstantC | G1: ConstantK | H1: UnitString

Sheet Matrices
A1: MatrixName | B1: OID | C1: Addable | D1: Maximum | E1: DownloadedFromObjectId | F1: SourceObjectId | G1: SourceUrlId
A2: Adverse Events | B2: AE | C2: TRUE | D2: 999 | E2: 12218 | F2: 0
A3: ALL_1_SSc | B3: ALL_1 | C3: FALSE | D3: 0 | E3: 12219 | F3: 1444
A4: ALL_2_IIM | B4: ALL_2 | C4: FALSE | D4: 0 | E4: 12220 | F4: 1444
A5: Baseline Period | B5: BASE | C5: FALSE | D5: 0 | E5: 12221 | F5: 0
A6: Apheresis collection Day & Withdrawal Visit & End of Study Visit | B6: COL1 | C6: FALSE | D6: 0 | E6: 12222 | F6: 0
A7: Second Apheresis collection Day | B7: COL2 | C7: TRUE | D7: 4 | E7: 12223 | F7: 0
A8: CRS ASTCT Criteria | B8: CRS | C8: TRUE | D8: 999 | E8: 12224 | F8: 0
A9: DEFAULT | B9: DEFAULT | C9: FALSE | D9: 0 | E9: 12225 | F9: 1444
A10: Lymphodepletion Pretreatment Period | B10: EC1 | C10: FALSE | D10: 0 | E10: 12226 | F10: 0
A11: GC012F Infusion | B11: EC2 | C11: FALSE | D11: 0 | E11: 12227 | F11: 0
A12: End of Study | B12: EOS2 | C12: FALSE | D12: 0 | E12: 12228 | F12: 0
A13: ICANS ASTCT Criteria | B13: ICANS | C13: TRUE | D13: 999 | E13: 12229 | F13: 0
... A34: Unscheduled Visit | B34: UNSCH | C34: TRUE | D34: 999 | E34: 12250 | F34: 0

Sheet Matrix1#AE
A1: Matrix: AE | B1: Subject | C1: SCR | D1: COL1 | E1: COL2 | F1: BASE | G1: EC1 | H1: EC2 | I1: SFU1 | J1: SFU2 | K1: SFU3 | L1: SFU4 | M1: SFU5 | N1: SFU6 | O1: SFU7 | P1: SFU8 | Q1: SFU9 | R1: SFU10 | S1: SFU11 | T1: SFU12 | U1: LFU1 | V1: LFU2 | W1: LFU3 | X1: LFU4 | Y1: LFU5 | Z1: LFU6 | AA1: LFUC | AB1: WS | AC1: EOS1 | AD1: SUR | AE1: GF | AF1: UNSCH | AG1: EOS2
A2: SC
A3: SV
A4: UNSCH
A5: DS1_IC
A6: DM
A7: MH
A8: CM1
A9: PR2
A10: SU
A11: PR1
A12: HEI
A13: WEI
... A86: AEYN
A87: AE | AE87: X
A88: SA
A89: CRS
A90: ICANS
A91: HLHMAS
A92: DD
A93: FU
A94: NEXTYN
A95: DS2_SCR
A96: DS3_WS
A97: DS4_EOS
A98: MH1
A99: MH2
... A104: CP4

Sheet Matrix2#ALL1
A1: Matrix: ALL_1 | B1: Subject | C1: SCR | D1: COL1 | E1: COL2 | F1: BASE | G1: EC1 | H1: EC2 | I1: SFU1 | J1: SFU2 | K1: SFU3 | L1: SFU4 | M1: SFU5 | N1: SFU6 | O1: SFU7 | P1: SFU8 | Q1: SFU9 | R1: SFU10 | S1: SFU11 | T1: SFU12 | U1: LFU1 | V1: LFU2 | W1: LFU3 | X1: LFU4 | Y1: LFU5 | Z1: LFU6 | AA1: LFUC | AB1: WS | AC1: EOS1 | AD1: SUR | AE1: GF | AF1: UNSCH | AG1: EOS2
A2: SC | B2: X
A3: SV | C3: X | D3: X | E3: X | F3: X | G3: X | H3: X | I3: X | J3: X | K3: X | L3: X | M3: X | N3: X | O3: X | P3: X | Q3: X | R3: X | S3: X | T3: X | U3: X | V3: X | W3: X | X3: X | Y3: X | Z3: X | AA3: X | AB3: X | AC3: X | AF3: X
A4: UNSCH | AF4: X
A5: DS1_IC | C5: X
A6: DM | C6: X
A7: MH | C7: X
A8: CM1 | C8: X
A9: PR2 | C9: X
A10: SU | C10: X
A11: PR1 | C11: X
A12: HEI | C12: X | AF12: X
A13: WEI | C13: X | D13: X | E13: X | G13: X | H13: X | M13: X | N13: X | O13: X | P13: X | Q13: X | R13: X | S13: X | T13: X | U13: X | V13: X | W13: X | X13: X | Y13: X | Z13: X | AA13: X | AB13: X | AC13: X | AF13: X
A14: CV1 | C14: X | AF14: X
A15: CV2 | C15: X | F15: X | P15: X | Q15: X | R15: X | S15: X | T15: X | U15: X | V15: X | W15: X | X15: X | Y15: X | Z15: X | AA15: X | AB15: X | AC15: X | AF15: X
A16: CV4 | AF16: X
A17: CV5 | AF17: X
A18: CV3 | F18: X | O18: X | AF18: X
A19: MK6 | AF19: X
A20: MK7 | AF20: X
A21: EG1 | C21: X | F21: X | H21: X | J21: X | L21: X | M21: X | N21: X | O21: X | P21: X | Q21: X | R21: X | S21: X | T21: X | AB21: X | AC21: X | AF21: X
A22: ECHO | C22: X | AB22: X | AC22: X | AF22: X
A23: SR | F23: X | M23: X | O23: X | R23: X | S23: X | T23: X | AA23: X | AB23: X | AC23: X | AF23: X
A24: EG2 | H24: X | AF24: X
A25: VS1 | C25: X | D25: X | E25: X | F25: X | G25: X | I25: X | J25: X | K25: X | L25: X | M25: X | N25: X | O25: X | P25: X | Q25: X | R25: X | S25: X | T25: X | U25: X | V25: X | W25: X | X25: X | Y25: X | Z25: X | AA25: X | AB25: X | AC25: X | AF25: X
A26: VS2 | H26: X
A27: PE | C27: X | AB27: X | AC27: X | AF27: X
A28: RE | C28: X | F28: X | M28: X | N28: X | O28: X | P28: X | Q28: X | R28: X | S28: X | T28: X | U28: X | V28: X | W28: X | X28: X | Y28: X | Z28: X | AA28: X | AB28: X | AC28: X | AF28: X
A29: LB8_RP | C29: X | F29: X | AB29: X | AC29: X | AF29: X
A30: LB9_PAT | AF30: X
A31: LB13_VAC | F31: X | H31: X | I31: X | J31: X | K31: X | L31: X | M31: X | N31: X | O31: X | P31: X | Q31: X | R31: X | S31: X | T31: X | U31: X | V31: X | W31: X | X31: X | Y31: X | Z31: X | AA31: X | AB31: X | AC31: X | AF31: X
A32: LB14_SER | C32: X | F32: X | H32: X | L32: X | M32: X | N32: X | O32: X | P32: X | Q32: X | R32: X | S32: X | T32: X | U32: X | V32: X | W32: X | X32: X | Y32: X | Z32: X | AA32: X | AB32: X | AC32: X | AF32: X
A33: LB19_SYP | C33: X | D33: X | E33: X | AF33: X
A34: LB16_VIR | C34: X | D34: X | E34: X | AF34: X
A35: LB17_HCV | C35: X | D35: X | E35: X | AF35: X
A36: LB18_HBV | C36: X | D36: X | E36: X | AF36: X
A37: LB10_ESR | C37: X | F37: X | M37: X | P37: X | R37: X | S37: X | T37: X | U37: X | V37: X | W37: X | X37: X | Y37: X | Z37: X | AA37: X | AB37: X | AC37: X | AF37: X
A38: LB11_HC | C38: X | F38: X | M38: X | P38: X | R38: X | S38: X | T38: X | U38: X | V38: X | W38: X | X38: X | Y38: X | Z38: X | AA38: X | AB38: X | AC38: X | AF38: X
A39: LB12_TUB | C39: X | AF39: X
A40: LB1_HEM | C40: X | D40: X | E40: X | F40: X | H40: X | I40: X | J40: X | K40: X | L40: X | M40: X | N40: X | O40: X | P40: X | Q40: X | R40: X | S40: X | T40: X | U40: X | V40: X | W40: X | X40: X | Y40: X | Z40: X | AA40: X | AB40: X | AC40: X | AF40: X
...

Sheet Matrix3#ALL2
A1: Matrix: ALL_2 | B1: Subject | C1: SCR | D1: COL1 | E1: COL2 | F1: BASE | G1: EC1 | H1: EC2 | I1: SFU1 | J1: SFU2 | K1: SFU3 | L1: SFU4 | M1: SFU5 | N1: SFU6 | O1: SFU7 | P1: SFU8 | Q1: SFU9 | R1: SFU10 | S1: SFU11 | T1: SFU12 | U1: LFU1 | V1: LFU2 | W1: LFU3 | X1: LFU4 | Y1: LFU5 | Z1: LFU6 | AA1: LFUC | AB1: WS | AC1: EOS1 | AD1: SUR | AE1: GF | AF1: UNSCH | AG1: EOS2
A2: SC | B2: X
A3: SV | C3: X | D3: X | E3: X | F3: X | G3: X | H3: X | I3: X | J3: X | K3: X | L3: X | M3: X | N3: X | O3: X | P3: X | Q3: X | R3: X | S3: X | T3: X | U3: X | V3: X | W3: X | X3: X | Y3: X | Z3: X | AA3: X | AB3: X | AC3: X | AF3: X
A4: UNSCH | AF4: X
A5: DS1_IC | C5: X
A6: DM | C6: X
A7: MH | C7: X
A8: CM1 | C8: X
A9: PR2 | C9: X
A10: SU | C10: X
A11: PR1 | C11: X
A12: HEI | C12: X | AF12: X
A13: WEI | C13: X | D13: X | E13: X | G13: X | H13: X | M13: X | N13: X | O13: X | P13: X | Q13: X | R13: X | S13: X | T13: X | U13: X | V13: X | W13: X | X13: X | Y13: X | Z13: X | AA13: X | AB13: X | AC13: X | AF13: X
A14: CV1 | C14: X | AF14: X
A15: CV2 | AF15: X
A16: CV4 | C16: X | F16: X | P16: X | Q16: X | R16: X | S16: X | T16: X | U16: X | V16: X | W16: X | X16: X | Y16: X | Z16: X | AA16: X | AB16: X | AC16: X | AF16: X
A17: CV5 | C17: X | F17: X | M17: X | N17: X | O17: X | P17: X | Q17: X | R17: X | S17: X | T17: X | U17: X | V17: X | W17: X | X17: X | Y17: X | Z17: X | AA17: X | AB17: X | AC17: X | AF17: X
A18: CV3 | AF18: X
A19: MK6 | C19: X | O19: X | P19: X | AF19: X
A20: MK7 | C20: X | O20: X | P20: X | AF20: X
A21: EG1 | C21: X | F21: X | H21: X | J21: X | L21: X | M21: X | N21: X | O21: X | P21: X | Q21: X | R21: X | S21: X | T21: X | AB21: X | AC21: X | AF21: X
A22: ECHO | C22: X | AB22: X | AC22: X | AF22: X
A23: SR | AF23: X
A24: EG2 | H24: X | AF24: X
A25: VS1 | C25: X | D25: X | E25: X | F25: X | G25: X | I25: X | J25: X | K25: X | L25: X | M25: X | N25: X | O25: X | P25: X | Q25: X | R25: X | S25: X | T25: X | U25: X | V25: X | W25: X | X25: X | Y25: X | Z25: X | AA25: X | AB25: X | AC25: X | AF25: X
A26: VS2 | H26: X
A27: PE | C27: X | AF27: X
A28: RE | C28: X | F28: X | M28: X | N28: X | O28: X | P28: X | Q28: X | R28: X | S28: X | T28: X | U28: X | V28: X | W28: X | X28: X | Y28: X | Z28: X | AA28: X | AB28: X | AC28: X | AF28: X
A29: LB8_RP | C29: X | F29: X | AB29: X | AC29: X | AF29: X
A30: LB9_PAT | C30: X | F30: X | H30: X | L30: X | M30: X | N30: X | O30: X | P30: X | Q30: X | R30: X | S30: X | T30: X | U30: X | V30: X | W30: X | X30: X | Y30: X | Z30: X | AA30: X | AB30: X | AC30: X | AF30: X
A31: LB13_VAC | F31: X | H31: X | I31: X | J31: X | K31: X | L31: X | M31: X | N31: X | O31: X | P31: X | Q31: X | R31: X | S31: X | T31: X | U31: X | V31: X | W31: X | X31: X | Y31: X | Z31: X | AA31: X | AB31: X | AC31: X | AF31: X
A32: LB14_SER | AF32: X
A33: LB19_SYP | C33: X | D33: X | E33: X | AF33: X
A34: LB16_VIR | C34: X | D34: X | E34: X | AF34: X
A35: LB17_HCV | C35: X | D35: X | E35: X | AF35: X
A36: LB18_HBV | C36: X | D36: X | E36: X | AF36: X
A37: LB10_ESR | AF37: X
A38: LB11_HC | AF38: X
A39: LB12_TUB | C39: X | AF39: X
A40: LB1_HEM | C40: X | D40: X | E40: X | F40: X | H40: X | I40: X | J40: X | K40: X | L40: X | M40: X | N40: X | O40: X | P40: X | Q40: X | R40: X | S40: X | T40: X | U40: X | V40: X | W40: X | X40: X | Y40: X | Z40: X | AA40: X | AB40: X | AC40: X | AF40: X
...

Sheet Matrix4#BASE
A1: Matrix: BASE | B1: Subject | C1: SCR | D1: COL1 | E1: COL2 | F1: BASE | G1: EC1 | H1: EC2 | I1: SFU1 | J1: SFU2 | K1: SFU3 | L1: SFU4 | M1: SFU5 | N1: SFU6 | O1: SFU7 | P1: SFU8 | Q1: SFU9 | R1: SFU10 | S1: SFU11 | T1: SFU12 | U1: LFU1 | V1: LFU2 | W1: LFU3 | X1: LFU4 | Y1: LFU5 | Z1: LFU6 | AA1: LFUC | AB1: WS | AC1: EOS1 | AD1: SUR | AE1: GF | AF1: UNSCH | AG1: EOS2
A2: SC
A3: SV | F3: X
A4: UNSCH
A5: DS1_IC
A6: DM
A7: MH
A8: CM1
A9: PR2
A10: SU
A11: PR1
A12: HEI
A13: WEI
A14: CV1
A15: CV2
... A93: FU
A94: NEXTYN | F94: X
A95: DS2_SCR
A96: DS3_WS
A97: DS4_EOS
A98: MH1
A99: MH2
A100: CP1
A101: CP17
A102: CP2
A103: CP3
A104: CP4

Sheet Matrix5#COL1
A1: Matrix: COL1 | B1: Subject | C1: SCR | D1: COL1 | E1: COL2 | F1: BASE | G1: EC1 | H1: EC2 | I1: SFU1 | J1: SFU2 | K1: SFU3 | L1: SFU4 | M1: SFU5 | N1: SFU6 | O1: SFU7 | P1: SFU8 | Q1: SFU9 | R1: SFU10 | S1: SFU11 | T1: SFU12 | U1: LFU1 | V1: LFU2 | W1: LFU3 | X1: LFU4 | Y1: LFU5 | Z1: LFU6 | AA1: LFUC | AB1: WS | AC1: EOS1 | AD1: SUR | AE1: GF | AF1: UNSCH | AG1: EOS2
A2: SC
A3: SV | D3: X | AB3: X | AC3: X
A4: UNSCH
A5: DS1_IC
A6: DM
A7: MH
A8: CM1
A9: PR2
A10: SU
A11: PR1
A12: HEI
A13: WEI
A14: CV1
A15: CV2
... A93: FU
A94: NEXTYN | D94: X
A95: DS2_SCR
A96: DS3_WS | AB96: X
A97: DS4_EOS
A98: MH1
A99: MH2
A100: CP1
A101: CP17
A102: CP2
A103: CP3
A104: CP4

Sheet Matrix6#COL2
A1: Matrix: COL2 | B1: Subject | C1: SCR | D1: COL1 | E1: COL2 | F1: BASE | G1: EC1 | H1: EC2 | I1: SFU1 | J1: SFU2 | K1: SFU3 | L1: SFU4 | M1: SFU5 | N1: SFU6 | O1: SFU7 | P1: SFU8 | Q1: SFU9 | R1: SFU10 | S1: SFU11 | T1: SFU12 | U1: LFU1 | V1: LFU2 | W1: LFU3 | X1: LFU4 | Y1: LFU5 | Z1: LFU6 | AA1: LFUC | AB1: WS | AC1: EOS1 | AD1: SUR | AE1: GF | AF1: UNSCH | AG1: EOS2
A2: SC
A3: SV | E3: X
A4: UNSCH
A5: DS1_IC
A6: DM
A7: MH
A8: CM1
A9: PR2
A10: SU
A11: PR1
A12: HEI
A13: WEI
A14: CV1
A15: CV2
... A93: FU
A94: NEXTYN | E94: X
A95: DS2_SCR
A96: DS3_WS
A97: DS4_EOS
A98: MH1
A99: MH2
A100: CP1
A101: CP17
A102: CP2
A103: CP3
A104: CP4

Sheet Matrix7#CRS
A1: Matrix: CRS | B1: Subject | C1: SCR | D1: COL1 | E1: COL2 | F1: BASE | G1: EC1 | H1: EC2 | I1: SFU1 | J1: SFU2 | K1: SFU3 | L1: SFU4 | M1: SFU5 | N1: SFU6 | O1: SFU7 | P1: SFU8 | Q1: SFU9 | R1: SFU10 | S1: SFU11 | T1: SFU12 | U1: LFU1 | V1: LFU2 | W1: LFU3 | X1: LFU4 | Y1: LFU5 | Z1: LFU6 | AA1: LFUC | AB1: WS | AC1: EOS1 | AD1: SUR | AE1: GF | AF1: UNSCH | AG1: EOS2
A2: SC
A3: SV
A4: UNSCH
A5: DS1_IC
A6: DM
A7: MH
A8: CM1
A9: PR2
A10: SU
A11: PR1
A12: HEI
A13: WEI
... A88: SA
A89: CRS | AE89: X
A90: ICANS
A91: HLHMAS
A92: DD
A93: FU
A94: NEXTYN
A95: DS2_SCR
A96: DS3_WS
A97: DS4_EOS
A98: MH1
A99: MH2
A100: CP1
A101: CP17
... A104: CP4

Sheet Matrix8#DEFAULT
A1: Matrix: DEFAULT | B1: Subject | C1: SCR | D1: COL1 | E1: COL2 | F1: BASE | G1: EC1 | H1: EC2 | I1: SFU1 | J1: SFU2 | K1: SFU3 | L1: SFU4 | M1: SFU5 | N1: SFU6 | O1: SFU7 | P1: SFU8 | Q1: SFU9 | R1: SFU10 | S1: SFU11 | T1: SFU12 | U1: LFU1 | V1: LFU2 | W1: LFU3 | X1: LFU4 | Y1: LFU5 | Z1: LFU6 | AA1: LFUC | AB1: WS | AC1: EOS1 | AD1: SUR | AE1: GF | AF1: UNSCH | AG1: EOS2
A2: SC
A3: SV | C3: X
A4: UNSCH
A5: DS1_IC | C5: X
A6: DM | C6: X
A7: MH | C7: X
A8: CM1 | C8: X
A9: PR2 | C9: X
A10: SU | C10: X
A11: PR1 | C11: X
A12: HEI | C12: X
A13: WEI | C13: X
A14: CV1 | C14: X
A15: CV2
A16: CV4
A17: CV5
A18: CV3
A19: MK6
A20: MK7
A21: EG1 | C21: X
A22: ECHO | C22: X
A23: SR
A24: EG2
A25: VS1 | C25: X
A26: VS2
A27: PE | C27: X
A28: RE | C28: X
A29: LB8_RP
A30: LB9_PAT
A31: LB13_VAC
A32: LB14_SER
A33: LB19_SYP | C33: X
A34: LB16_VIR | C34: X
A35: LB17_HCV | C35: X
A36: LB18_HBV | C36: X
A37: LB10_ESR
A38: LB11_HC
A39: LB12_TUB | C39: X
A40: LB1_HEM | C40: X
...

Sheet Matrix9#EC1
A1: Matrix: EC1 | B1: Subject | C1: SCR | D1: COL1 | E1: COL2 | F1: BASE | G1: EC1 | H1: EC2 | I1: SFU1 | J1: SFU2 | K1: SFU3 | L1: SFU4 | M1: SFU5 | N1: SFU6 | O1: SFU7 | P1: SFU8 | Q1: SFU9 | R1: SFU10 | S1: SFU11 | T1: SFU12 | U1: LFU1 | V1: LFU2 | W1: LFU3 | X1: LFU4 | Y1: LFU5 | Z1: LFU6 | AA1: LFUC | AB1: WS | AC1: EOS1 | AD1: SUR | AE1: GF | AF1: UNSCH | AG1: EOS2
A2: SC
A3: SV | G3: X
A4: UNSCH
A5: DS1_IC
A6: DM
A7: MH
A8: CM1
A9: PR2
A10: SU
A11: PR1
A12: HEI
A13: WEI
A14: CV1
A15: CV2
... A93: FU
A94: NEXTYN | G94: X
A95: DS2_SCR
A96: DS3_WS
A97: DS4_EOS
A98: MH1
A99: MH2
A100: CP1
A101: CP17
A102: CP2
A103: CP3
A104: CP4

Sheet Matrix10#EC2
A1: Matrix: EC2 | B1: Subject | C1: SCR | D1: COL1 | E1: COL2 | F1: BASE | G1: EC1 | H1: EC2 | I1: SFU1 | J1: SFU2 | K1: SFU3 | L1: SFU4 | M1: SFU5 | N1: SFU6 | O1: SFU7 | P1: SFU8 | Q1: SFU9 | R1: SFU10 | S1: SFU11 | T1: SFU12 | U1: LFU1 | V1: LFU2 | W1: LFU3 | X1: LFU4 | Y1: LFU5 | Z1: LFU6 | AA1: LFUC | AB1: WS | AC1: EOS1 | AD1: SUR | AE1: GF | AF1: UNSCH | AG1: EOS2
A2: SC
A3: SV | H3: X
A4: UNSCH
A5: DS1_IC
A6: DM
A7: MH
A8: CM1
A9: PR2
A10: SU
A11: PR1
A12: HEI
A13: WEI
A14: CV1
A15: CV2
... A93: FU
A94: NEXTYN | H94: X
A95: DS2_SCR
A96: DS3_WS
A97: DS4_EOS
A98: MH1
A99: MH2
A100: CP1
A101: CP17
A102: CP2
A103: CP3
A104: CP4

Sheet Matrix11#EOS2
A1: Matrix: EOS2 | B1: Subject | C1: SCR | D1: COL1 | E1: COL2 | F1: BASE | G1: EC1 | H1: EC2 | I1: SFU1 | J1: SFU2 | K1: SFU3 | L1: SFU4 | M1: SFU5 | N1: SFU6 | O1: SFU7 | P1: SFU8 | Q1: SFU9 | R1: SFU10 | S1: SFU11 | T1: SFU12 | U1: LFU1 | V1: LFU2 | W1: LFU3 | X1: LFU4 | Y1: LFU5 | Z1: LFU6 | AA1: LFUC | AB1: WS | AC1: EOS1 | AD1: SUR | AE1: GF | AF1: UNSCH | AG1: EOS2
A2: SC
A3: SV
A4: UNSCH
A5: DS1_IC
A6: DM
A7: MH
A8: CM1
A9: PR2
A10: SU
A11: PR1
A12: HEI
A13: WEI
... A96: DS3_WS
A97: DS4_EOS | AG97: X
A98: MH1
A99: MH2
A100: CP1
A101: CP17
A102: CP2
A103: CP3
A104: CP4

Sheet Matrix12#ICANS
A1: Matrix: ICANS | B1: Subject | C1: SCR | D1: COL1 | E1: COL2 | F1: BASE | G1: EC1 | H1: EC2 | I1: SFU1 | J1: SFU2 | K1: SFU3 | L1: SFU4 | M1: SFU5 | N1: SFU6 | O1: SFU7 | P1: SFU8 | Q1: SFU9 | R1: SFU10 | S1: SFU11 | T1: SFU12 | U1: LFU1 | V1: LFU2 | W1: LFU3 | X1: LFU4 | Y1: LFU5 | Z1: LFU6 | AA1: LFUC | AB1: WS | AC1: EOS1 | AD1: SUR | AE1: GF | AF1: UNSCH | AG1: EOS2
A2: SC
A3: SV
A4: UNSCH
A5: DS1_IC
A6: DM
A7: MH
A8: CM1
A9: PR2
A10: SU
A11: PR1
A12: HEI
A13: WEI
... A89: CRS
A90: ICANS | AE90: X
A91: HLHMAS
A92: DD
A93: FU
A94: NEXTYN
A95: DS2_SCR
A96: DS3_WS
A97: DS4_EOS
A98: MH1
A99: MH2
A100: CP1
A101: CP17
A102: CP2
... A104: CP4

Sheet Matrix13#LFU1
A1: Matrix: LFU1 | B1: Subject | C1: SCR | D1: COL1 | E1: COL2 | F1: BASE | G1: EC1 | H1: EC2 | I1: SFU1 | J1: SFU2 | K1: SFU3 | L1: SFU4 | M1: SFU5 | N1: SFU6 | O1: SFU7 | P1: SFU8 | Q1: SFU9 | R1: SFU10 | S1: SFU11 | T1: SFU12 | U1: LFU1 | V1: LFU2 | W1: LFU3 | X1: LFU4 | Y1: LFU5 | Z1: LFU6 | AA1: LFUC | AB1: WS | AC1: EOS1 | AD1: SUR | AE1: GF | AF1: UNSCH | AG1: EOS2
A2: SC
A3: SV | U3: X
A4: UNSCH
A5: DS1_IC
A6: DM
A7: MH
A8: CM1
A9: PR2
A10: SU
A11: PR1
A12: HEI
A13: WEI
A14: CV1
A15: CV2
... A93: FU
A94: NEXTYN | U94: X
A95: DS2_SCR
A96: DS3_WS
A97: DS4_EOS
A98: MH1
A99: MH2
A100: CP1
A101: CP17
A102: CP2
A103: CP3
A104: CP4

Sheet Matrix14#LFU2
A1: Matrix: LFU2 | B1: Subject | C1: SCR | D1: COL1 | E1: COL2 | F1: BASE | G1: EC1 | H1: EC2 | I1: SFU1 | J1: SFU2 | K1: SFU3 | L1: SFU4 | M1: SFU5 | N1: SFU6 | O1: SFU7 | P1: SFU8 | Q1: SFU9 | R1: SFU10 | S1: SFU11 | T1: SFU12 | U1: LFU1 | V1: LFU2 | W1: LFU3 | X1: LFU4 | Y1: LFU5 | Z1: LFU6 | AA1: LFUC | AB1: WS | AC1: EOS1 | AD1: SUR | AE1: GF | AF1: UNSCH | AG1: EOS2
A2: SC
A3: SV | V3: X
A4: UNSCH
A5: DS1_IC
A6: DM
A7: MH
A8: CM1
A9: PR2
A10: SU
A11: PR1
A12: HEI
A13: WEI
A14: CV1
A15: CV2
... A93: FU
A94: NEXTYN | V94: X
A95: DS2_SCR
A96: DS3_WS
A97: DS4_EOS
A98: MH1
A99: MH2
A100: CP1
A101: CP17
A102: CP2
A103: CP3
A104: CP4

Sheet Matrix15#LFU3
A1: Matrix: LFU3 | B1: Subject | C1: SCR | D1: COL1 | E1: COL2 | F1: BASE | G1: EC1 | H1: EC2 | I1: SFU1 | J1: SFU2 | K1: SFU3 | L1: SFU4 | M1: SFU5 | N1: SFU6 | O1: SFU7 | P1: SFU8 | Q1: SFU9 | R1: SFU10 | S1: SFU11 | T1: SFU12 | U1: LFU1 | V1: LFU2 | W1: LFU3 | X1: LFU4 | Y1: LFU5 | Z1: LFU6 | AA1: LFUC | AB1: WS | AC1: EOS1 | AD1: SUR | AE1: GF | AF1: UNSCH | AG1: EOS2
A2: SC
A3: SV | W3: X
A4: UNSCH
A5: DS1_IC
A6: DM
A7: MH
A8: CM1
A9: PR2
A10: SU
A11: PR1
A12: HEI
A13: WEI
A14: CV1
A15: CV2
... A93: FU
A94: NEXTYN | W94: X
A95: DS2_SCR
A96: DS3_WS
A97: DS4_EOS
A98: MH1
A99: MH2
A100: CP1
A101: CP17
A102: CP2
A103: CP3
A104: CP4

Sheet Matrix16#LFU4
A1: Matrix: LFU4 | B1: Subject | C1: SCR | D1: COL1 | E1: COL2 | F1: BASE | G1: EC1 | H1: EC2 | I1: SFU1 | J1: SFU2 | K1: SFU3 | L1: SFU4 | M1: SFU5 | N1: SFU6 | O1: SFU7 | P1: SFU8 | Q1: SFU9 | R1: SFU10 | S1: SFU11 | T1: SFU12 | U1: LFU1 | V1: LFU2 | W1: LFU3 | X1: LFU4 | Y1: LFU5 | Z1: LFU6 | AA1: LFUC | AB1: WS | AC1: EOS1 | AD1: SUR | AE1: GF | AF1: UNSCH | AG1: EOS2
A2: SC
A3: SV | X3: X
A4: UNSCH
A5: DS1_IC
A6: DM
A7: MH
A8: CM1
A9: PR2
A10: SU
A11: PR1
A12: HEI
A13: WEI
A14: CV1
A15: CV2
... A93: FU
A94: NEXTYN | X94: X
A95: DS2_SCR
A96: DS3_WS
A97: DS4_EOS
A98: MH1
A99: MH2
A100: CP1
A101: CP17
A102: CP2
A103: CP3
A104: CP4

Sheet Matrix17#LFU5
A1: Matrix: LFU5 | B1: Subject | C1: SCR | D1: COL1 | E1: COL2 | F1: BASE | G1: EC1 | H1: EC2 | I1: SFU1 | J1: SFU2 | K1: SFU3 | L1: SFU4 | M1: SFU5 | N1: SFU6 | O1: SFU7 | P1: SFU8 | Q1: SFU9 | R1: SFU10 | S1: SFU11 | T1: SFU12 | U1: LFU1 | V1: LFU2 | W1: LFU3 | X1: LFU4 | Y1: LFU5 | Z1: LFU6 | AA1: LFUC | AB1: WS | AC1: EOS1 | AD1: SUR | AE1: GF | AF1: UNSCH | AG1: EOS2
A2: SC
A3: SV | Y3: X
A4: UNSCH
A5: DS1_IC
A6: DM
A7: MH
A8: CM1
A9: PR2
A10: SU
A11: PR1
A12: HEI
A13: WEI
A14: CV1
A15: CV2
... A93: FU
A94: NEXTYN | Y94: X
A95: DS2_SCR
A96: DS3_WS
A97: DS4_EOS
A98: MH1
A99: MH2
A100: CP1
A101: CP17
A102: CP2
A103: CP3
A104: CP4

Sheet Matrix18#LFU6
A1: Matrix: LFU6 | B1: Subject | C1: SCR | D1: COL1 | E1: COL2 | F1: BASE | G1: EC1 | H1: EC2 | I1: SFU1 | J1: SFU2 | K1: SFU3 | L1: SFU4 | M1: SFU5 | N1: SFU6 | O1: SFU7 | P1: SFU8 | Q1: SFU9 | R1: SFU10 | S1: SFU11 | T1: SFU12 | U1: LFU1 | V1: LFU2 | W1: LFU3 | X1: LFU4 | Y1: LFU5 | Z1: LFU6 | AA1: LFUC | AB1: WS | AC1: EOS1 | AD1: SUR | AE1: GF | AF1: UNSCH | AG1: EOS2
A2: SC
A3: SV | Z3: X
A4: UNSCH
A5: DS1_IC
A6: DM
A7: MH
A8: CM1
A9: PR2
A10: SU
A11: PR1
A12: HEI
A13: WEI
A14: CV1
A15: CV2
... A93: FU
A94: NEXTYN | Z94: X
A95: DS2_SCR
A96: DS3_WS
A97: DS4_EOS
A98: MH1
A99: MH2
A100: CP1
A101: CP17
A102: CP2
A103: CP3
A104: CP4

Sheet Matrix19#LFUC
A1: Matrix: LFUC | B1: Subject | C1: SCR | D1: COL1 | E1: COL2 | F1: BASE | G1: EC1 | H1: EC2 | I1: SFU1 | J1: SFU2 | K1: SFU3 | L1: SFU4 | M1: SFU5 | N1: SFU6 | O1: SFU7 | P1: SFU8 | Q1: SFU9 | R1: SFU10 | S1: SFU11 | T1: SFU12 | U1: LFU1 | V1: LFU2 | W1: LFU3 | X1: LFU4 | Y1: LFU5 | Z1: LFU6 | AA1: LFUC | AB1: WS | AC1: EOS1 | AD1: SUR | AE1: GF | AF1: UNSCH | AG1: EOS2
A2: SC
A3: SV | AA3: X
A4: UNSCH
A5: DS1_IC
A6: DM
A7: MH
A8: CM1
A9: PR2
A10: SU
A11: PR1
A12: HEI
A13: WEI
A14: CV1
A15: CV2
... A93: FU
A94: NEXTYN | AA94: X
A95: DS2_SCR
A96: DS3_WS
A97: DS4_EOS
A98: MH1
A99: MH2
A100: CP1
A101: CP17
A102: CP2
A103: CP3
A104: CP4

Sheet Matrix20#SFU1
A1: Matrix: SFU1 | B1: Subject | C1: SCR | D1: COL1 | E1: COL2 | F1: BASE | G1: EC1 | H1: EC2 | I1: SFU1 | J1: SFU2 | K1: SFU3 | L1: SFU4 | M1: SFU5 | N1: SFU6 | O1: SFU7 | P1: SFU8 | Q1: SFU9 | R1: SFU10 | S1: SFU11 | T1: SFU12 | U1: LFU1 | V1: LFU2 | W1: LFU3 | X1: LFU4 | Y1: LFU5 | Z1: LFU6 | AA1: LFUC | AB1: WS | AC1: EOS1 | AD1: SUR | AE1: GF | AF1: UNSCH | AG1: EOS2
A2: SC
A3: SV | I3: X
A4: UNSCH
A5: DS1_IC
A6: DM
A7: MH
A8: CM1
A9: PR2
A10: SU
A11: PR1
A12: HEI
A13: WEI
A14: CV1
A15: CV2
... A92: DD
A93: FU | AD93: X
A94: NEXTYN | I94: X
A95: DS2_SCR
A96: DS3_WS
A97: DS4_EOS
A98: MH1
A99: MH2
A100: CP1
A101: CP17
A102: CP2
A103: CP3
A104: CP4

Sheet Matrix21#SFU10
A1: Matrix: SFU10 | B1: Subject | C1: SCR | D1: COL1 | E1: COL2 | F1: BASE | G1: EC1 | H1: EC2 | I1: SFU1 | J1: SFU2 | K1: SFU3 | L1: SFU4 | M1: SFU5 | N1: SFU6 | O1: SFU7 | P1: SFU8 | Q1: SFU9 | R1: SFU10 | S1: SFU11 | T1: SFU12 | U1: LFU1 | V1: LFU2 | W1: LFU3 | X1: LFU4 | Y1: LFU5 | Z1: LFU6 | AA1: LFUC | AB1: WS | AC1: EOS1 | AD1: SUR | AE1: GF | AF1: UNSCH | AG1: EOS2
A2: SC
A3: SV | R3: X
A4: UNSCH
A5: DS1_IC
A6: DM
A7: MH
A8: CM1
A9: PR2
A10: SU
A11: PR1
A12: HEI
A13: WEI
A14: CV1
A15: CV2
... A93: FU
A94: NEXTYN | R94: X
A95: DS2_SCR
A96: DS3_WS
A97: DS4_EOS
A98: MH1
A99: MH2
A100: CP1
A101: CP17
A102: CP2
A103: CP3
A104: CP4

Sheet Matrix22#SFU11
A1: Matrix: SFU11 | B1: Subject | C1: SCR | D1: COL1 | E1: COL2 | F1: BASE | G1: EC1 | H1: EC2 | I1: SFU1 | J1: SFU2 | K1: SFU3 | L1: SFU4 | M1: SFU5 | N1: SFU6 | O1: SFU7 | P1: SFU8 | Q1: SFU9 | R1: SFU10 | S1: SFU11 | T1: SFU12 | U1: LFU1 | V1: LFU2 | W1: LFU3 | X1: LFU4 | Y1: LFU5 | Z1: LFU6 | AA1: LFUC | AB1: WS | AC1: EOS1 | AD1: SUR | AE1: GF | AF1: UNSCH | AG1: EOS2
A2: SC
A3: SV | S3: X
A4: UNSCH
A5: DS1_IC
A6: DM
A7: MH
A8: CM1
A9: PR2
A10: SU
A11: PR1
A12: HEI
A13: WEI
A14: CV1
A15: CV2
... A93: FU
A94: NEXTYN | S94: X
A95: DS2_SCR
A96: DS3_WS
A97: DS4_EOS
A98: MH1
A99: MH2
A100: CP1
A101: CP17
A102: CP2
A103: CP3
A104: CP4

Sheet Matrix23#SFU12
A1: Matrix: SFU12 | B1: Subject | C1: SCR | D1: COL1 | E1: COL2 | F1: BASE | G1: EC1 | H1: EC2 | I1: SFU1 | J1: SFU2 | K1: SFU3 | L1: SFU4 | M1: SFU5 | N1: SFU6 | O1: SFU7 | P1: SFU8 | Q1: SFU9 | R1: SFU10 | S1: SFU11 | T1: SFU12 | U1: LFU1 | V1: LFU2 | W1: LFU3 | X1: LFU4 | Y1: LFU5 | Z1: LFU6 | AA1: LFUC | AB1: WS | AC1: EOS1 | AD1: SUR | AE1: GF | AF1: UNSCH | AG1: EOS2
A2: SC
A3: SV | T3: X
A4: UNSCH
A5: DS1_IC
A6: DM
A7: MH
A8: CM1
A9: PR2
A10: SU
A11: PR1
A12: HEI
A13: WEI
A14: CV1
A15: CV2
... A93: FU
A94: NEXTYN | T94: X
A95: DS2_SCR
A96: DS3_WS
A97: DS4_EOS
A98: MH1
A99: MH2
A100: CP1
A101: CP17
A102: CP2
A103: CP3
A104: CP4

Sheet Matrix24#SFU2
A1: Matrix: SFU2 | B1: Subject | C1: SCR | D1: COL1 | E1: COL2 | F1: BASE | G1: EC1 | H1: EC2 | I1: SFU1 | J1: SFU2 | K1: SFU3 | L1: SFU4 | M1: SFU5 | N1: SFU6 | O1: SFU7 | P1: SFU8 | Q1: SFU9 | R1: SFU10 | S1: SFU11 | T1: SFU12 | U1: LFU1 | V1: LFU2 | W1: LFU3 | X1: LFU4 | Y1: LFU5 | Z1: LFU6 | AA1: LFUC | AB1: WS | AC1: EOS1 | AD1: SUR | AE1: GF | AF1: UNSCH | AG1: EOS2
A2: SC
A3: SV | J3: X
A4: UNSCH
A5: DS1_IC
A6: DM
A7: MH
A8: CM1
A9: PR2
A10: SU
A11: PR1
A12: HEI
A13: WEI
A14: CV1
A15: CV2
... A93: FU
A94: NEXTYN | J94: X
A95: DS2_SCR
A96: DS3_WS
A97: DS4_EOS
A98: MH1
A99: MH2
A100: CP1
A101: CP17
A102: CP2
A103: CP3
A104: CP4

Sheet Matrix25#SFU3
A1: Matrix: SFU3 | B1: Subject | C1: SCR | D1: COL1 | E1: COL2 | F1: BASE | G1: EC1 | H1: EC2 | I1: SFU1 | J1: SFU2 | K1: SFU3 | L1: SFU4 | M1: SFU5 | N1: SFU6 | O1: SFU7 | P1: SFU8 | Q1: SFU9 | R1: SFU10 | S1: SFU11 | T1: SFU12 | U1: LFU1 | V1: LFU2 | W1: LFU3 | X1: LFU4 | Y1: LFU5 | Z1: LFU6 | AA1: LFUC | AB1: WS | AC1: EOS1 | AD1: SUR | AE1: GF | AF1: UNSCH | AG1: EOS2
A2: SC
A3: SV | K3: X
A4: UNSCH
A5: DS1_IC
A6: DM
A7: MH
A8: CM1
A9: PR2
A10: SU
A11: PR1
A12: HEI
A13: WEI
A14: CV1
A15: CV2
... A93: FU
A94: NEXTYN | K94: X
A95: DS2_SCR
A96: DS3_WS
A97: DS4_EOS
A98: MH1
A99: MH2
A100: CP1
A101: CP17
A102: CP2
A103: CP3
A104: CP4

Sheet Matrix26#SFU4
A1: Matrix: SFU4 | B1: Subject | C1: SCR | D1: COL1 | E1: COL2 | F1: BASE | G1: EC1 | H1: EC2 | I1: SFU1 | J1: SFU2 | K1: SFU3 | L1: SFU4 | M1: SFU5 | N1: SFU6 | O1: SFU7 | P1: SFU8 | Q1: SFU9 | R1: SFU10 | S1: SFU11 | T1: SFU12 | U1: LFU1 | V1: LFU2 | W1: LFU3 | X1: LFU4 | Y1: LFU5 | Z1: LFU6 | AA1: LFUC | AB1: WS | AC1: EOS1 | AD1: SUR | AE1: GF | AF1: UNSCH | AG1: EOS2
A2: SC
A3: SV | L3: X
A4: UNSCH
A5: DS1_IC
A6: DM
A7: MH
A8: CM1
A9: PR2
A10: SU
A11: PR1
A12: HEI
A13: WEI
A14: CV1
A15: CV2
... A93: FU
A94: NEXTYN | L94: X
A95: DS2_SCR
A96: DS3_WS
A97: DS4_EOS
A98: MH1
A99: MH2
A100: CP1
A101: CP17
A102: CP2
A103: CP3
A104: CP4

Sheet Matrix27#SFU5
